Workbook

Sheet Read Me
A1: Gym Exercise Compendium & Workout Builder
A4: The sheets
A5: Exercise Library | B5: 167 exercises: equipment, movement pattern, primary and secondary muscle groups, and a prescription profile. Add your own rows at the bottom.
A6: Warm-Up Library | B6: 49 drills, each tagged with the movement pattern or muscle group that should trigger it, a phase, a priority and a duration.
A7: Mobility Library | B7: 43 mobility exercises, all doable on a yoga mat with no equipment. Tagged by target muscle group.
A8: Prescriptions | B8: The engine. Per profile and goal: sets, reps, load, rest — plus the numbers used for the time estimate. Edit these and every workout sheet follows.
A9: Workout A / B / C | B9: Warm-up, main session, cool-down and a time estimate on one page. Copy a tab (right-click → Move or Copy) for more sessions.
A10: Training Log | B10: One row per set. Volume and estimated 1RM calculate themselves.
A11: Progress | B11: Automatic summary per exercise: best estimated 1RM, heaviest set, total volume, last trained.
A13: How the warm-up builds itself
A14: Step 1 | B14: You pick your main exercises. Their movement patterns and muscle groups are what the warm-up reacts to — choose a squat and the squat drills become available, choose a carry and grip prep appears.
A15: Step 2 | B15: You set a warm-up budget in minutes. The sheet works down the drill list in priority order and keeps adding until the budget runs out. Low budget means you get the general raise and your ramp-up sets; a bigger budget buys mobility and activation work on top.
A16: Step 3 | B16: Nothing is locked. Widen the budget, or reorder the Priority column in the Warm-Up Library if you disagree with what gets cut first.
A17: Cool-down | B17: Works the same way, but triggers off the muscle groups you actually trained — primary and secondary. Set the budget to 0 if you want to skip it.
A19: How the time estimate works
A20: Per exercise | B20: Sets × (work time per set + rest) + set-up time. The three numbers come from the Prescriptions sheet, so a strength session with 4-minute rests estimates far longer than the same exercises done for endurance.
A21: Set-up time | B21: A flat allowance per exercise for walking over, loading the bar and adjusting the machine. It sits on the Prescriptions sheet — 90 seconds by default. Raise it for a busy gym.
A22: Total | B22: Warm-up + main session + cool-down, shown in minutes and as h:mm. Treat it as ±15%: it can't know how long you spend chatting or waiting for a rack.
A24: Colour legend
A25: Yellow cells | B25: You type here.
A26: Grey cells | B26: Calculated — don't overwrite, or you break the automation.
A27: White cells | B27: Reference data you can edit if you want to.
A29: Notes on the numbers
A30: Loads | B30: All loads in kilograms. Percentages refer to your one-rep max for that exercise. Suggested kilos are rounded to the nearest 2.5 kg. Back Squat has an example 1RM of 100 kg filled in so you can see the automation working — replace it with your own.
A31: Estimated 1RM | B31: Training Log column I uses the Epley formula: weight × (1 + reps ÷ 30). Reliable up to about 10 reps, optimistic above that.
A32: Carries | B32: For carry exercises, 'Your 1RM' means the heaviest total load you can carry for roughly 20 m.
A33: Bodyweight & plyometrics | B33: No percentage is prescribed — these are governed by quality and speed, not load.
A34: Prescription source | B34: Set/rep/load/rest ranges follow standard strength & conditioning practice (ACSM and NSCA resistance-training guidelines). Starting points, not prescriptions.

Sheet Exercise Library
A1: Exercise Library
A2: Add your own exercises on the first empty row. Use the same wording for Equipment, Movement pattern, Primary muscle and Prescription profile as the rows above, or the workout sheets won't find them.
A4: ID | B4: Exercise | C4: Övning (SV) | D4: Equipment | E4: Movement pattern | F4: Primary muscle | G4: Secondary muscles | H4: Prescription profile | I4: Cue / note | J4: Your 1RM (kg)
A5: 1 | B5: Back Squat | C5: Knäböj | D5: Barbell | E5: Squat | F5: Quads | G5: Glutes, Hamstrings, Core | H5: Heavy compound | I5: Brace before you unrack; knees track over toes. [1RM = example value, replace it] | J5: 100
A6: 2 | B6: Front Squat | C6: Frontböj | D6: Barbell | E6: Squat | F6: Quads | G6: Core, Glutes, Back | H6: Heavy compound | I6: Elbows high; upright torso.
A7: 3 | B7: Pause Squat | C7: Pausknäböj | D7: Barbell | E7: Squat | F7: Quads | G7: Glutes, Core | H7: Heavy compound | I7: 2–3 s pause in the hole, stay tight.
A8: 4 | B8: Box Squat | C8: Boxknäböj | D8: Barbell | E8: Squat | F8: Quads | G8: Glutes, Hamstrings | H8: Heavy compound | I8: Sit back to the box, don't relax on it.
A9: 5 | B9: Overhead Squat | C9: Överhuvudböj | D9: Barbell | E9: Squat | F9: Quads | G9: Shoulders, Core, Back | H9: Compound | I9: Mobility-limited for most; start with a stick.
A10: 6 | B10: Zercher Squat | C10: Zercherböj | D10: Barbell | E10: Squat | F10: Quads | G10: Core, Back, Biceps | H10: Compound | I10: Bar in elbow crease; use a towel for comfort.
A11: 7 | B11: Safety Bar Squat | C11: Knäböj med safety bar | D11: Barbell | E11: Squat | F11: Quads | G11: Glutes, Back | H11: Heavy compound | I11: Shoulder-friendly squat variation.
A12: 8 | B12: Goblet Squat | C12: Gobletböj | D12: Dumbbell/Kettlebell | E12: Squat | F12: Quads | G12: Glutes, Core | H12: Compound | I12: Great teaching tool and warm-up.
A13: 9 | B13: Hack Squat (Machine) | C13: Hackböj i maskin | D13: Machine | E13: Squat | F13: Quads | G13: Glutes | H13: Compound | I13: Fixed path; heavy quad emphasis.
A14: 10 | B14: Leg Press | C14: Benpress | D14: Machine | E14: Squat | F14: Quads | G14: Glutes, Hamstrings | H14: Compound | I14: Don't let the lower back round at the bottom.
A15: 11 | B15: Belt Squat | C15: Bältesböj | D15: Machine | E15: Squat | F15: Quads | G15: Glutes | H15: Compound | I15: Loads the legs without loading the spine.
A16: 12 | B16: Bodyweight Squat | C16: Kroppsviktsböj | D16: Bodyweight | E16: Squat | F16: Quads | G16: Glutes, Core | H16: Compound | I16: Warm-up and endurance staple.
A17: 13 | B17: Pistol Squat | C17: Pistolböj | D17: Bodyweight | E17: Squat | F17: Quads | G17: Glutes, Core | H17: Compound | I17: Assist with a band or counterweight to learn.
... A124: 120 | B124: Ab Wheel Rollout | C124: Rullhjul | D124: Bodyweight/Rings | E124: Core/Anti-movement | F124: Core | G124: Back, Shoulders | H124: Core | I124: Anti-extension; go only as far as you can brace.
A125: 121 | B125: Cable Crunch | C125: Kabelcrunch | D125: Cable | E125: Core/Anti-movement | F125: Core | H125: Core | I125: Flex the spine, don't hinge at the hips.
A126: 122 | B126: Russian Twist | C126: Rysk twist | D126: Bodyweight/Rings | E126: Core/Anti-movement | F126: Core | G126: Shoulders | H126: Core | I126: Rotate from the trunk, chest follows hands.
A127: 123 | B127: Hollow Body Hold | C127: Hollow hold | D127: Bodyweight/Rings | E127: Core/Anti-movement | F127: Core | G127: Quads | H127: Core | I127: Lower back pressed down throughout.
A128: 124 | B128: Copenhagen Plank | C128: Köpenhamnsplanka | D128: Bodyweight/Rings | E128: Core/Anti-movement | F128: Adductors | G128: Core | H128: Core | I128: Strong groin/adductor builder; start short.
A129: 125 | B129: Reverse Crunch | C129: Omvänd crunch | D129: Bodyweight/Rings | E129: Core/Anti-movement | F129: Core | H129: Core | I129: Curl the pelvis up, don't just swing the legs.
A130: 126 | B130: Landmine Rotation | C130: Landminerotation | D130: Barbell | E130: Core/Anti-movement | F130: Core | G130: Shoulders, Glutes | H130: Core | I130: Let the feet pivot.
A131: 127 | B131: L-Sit | C131: L-sit | D131: Bodyweight/Rings | E131: Core/Anti-movement | F131: Core | G131: Triceps, Quads | H131: Core | I131: Push the floor away; depress the shoulders.
A132: 128 | B132: Ring Support Hold | C132: Stödhäng i ringar | D132: Bodyweight/Rings | E132: Core/Anti-movement | F132: Shoulders | G132: Core, Triceps | H132: Core | I132: Rings turned out, arms locked.
A133: 129 | B133: Bear Crawl | C133: Björngång | D133: Bodyweight/Rings | E133: Core/Anti-movement | F133: Core | G133: Shoulders, Quads | H133: Core | I133: Hips low, knees hovering.
A134: 130 | B134: Farmer's Walk | C134: Farmer's walk | D134: Dumbbell/Kettlebell | E134: Carry | F134: Traps | G134: Forearms, Core, Glutes | H134: Carry | I134: Tall posture; grip usually fails first.
A135: 131 | B135: Suitcase Carry | C135: Resväskebärning | D135: Dumbbell/Kettlebell | E135: Carry | F135: Core | G135: Traps, Forearms | H135: Carry | I135: Anti-lateral flexion; don't lean.
A136: 132 | B136: Front Rack Carry | C136: Frontrackbärning | D136: Dumbbell/Kettlebell | E136: Carry | F136: Core | G136: Back, Shoulders | H136: Carry | I136: Elbows up, ribs down.
A137: 133 | B137: Overhead Carry | C137: Överhuvudbärning | D137: Dumbbell/Kettlebell | E137: Carry | F137: Shoulders | G137: Core, Traps | H137: Carry | I137: Locked elbows, active shoulders.
A138: 134 | B138: Zercher Carry | C138: Zercherbärning | D138: Barbell | E138: Carry | F138: Core | G138: Back, Quads | H138: Carry | I138: Very high trunk demand.
A139: 135 | B139: Sled Push | C139: Slädpress | D139: Machine | E139: Carry | F139: Quads | G139: Glutes, Calves | H139: Carry | I139: No eccentric — easy to recover from.
A140: 136 | B140: Sled Drag | C140: Slädsläp | D140: Machine | E140: Carry | F140: Hamstrings | G140: Glutes, Quads | H140: Carry | I140: Backwards drag is great for the knees.
A141: 137 | B141: Barbell Curl | C141: Skivstångscurl | D141: Barbell | E141: Isolation | F141: Biceps | G141: Forearms | H141: Isolation | I141: Elbows pinned to the sides.
... A147: 143 | B147: Reverse Curl | C147: Omvänd curl | D147: Barbell | E147: Isolation | F147: Forearms | G147: Biceps | H147: Isolation | I147: Pronated grip; builds forearm mass.
A148: 144 | B148: Triceps Pushdown | C148: Triceps pushdown | D148: Cable | E148: Isolation | F148: Triceps | H148: Isolation | I148: Elbows still, full lockout.
A149: 145 | B149: Overhead Triceps Extension | C149: Fransk press | D149: Dumbbell/Kettlebell | E149: Isolation | F149: Triceps | H149: Isolation | I149: Stretches the long head.
A150: 146 | B150: Skull Crusher | C150: Skullcrusher | D150: Barbell | E150: Isolation | F150: Triceps | H150: Isolation | I150: Lower behind the head, not to the nose.
A151: 147 | B151: Triceps Kickback | C151: Triceps kickback | D151: Dumbbell/Kettlebell | E151: Isolation | F151: Triceps | H151: Isolation | I151: Light weight, peak contraction.
A152: 148 | B152: Wrist Curl | C152: Handledscurl | D152: Dumbbell/Kettlebell | E152: Isolation | F152: Forearms | H152: Isolation | I152: High reps; grip and forearm health.
...

Sheet Warm-Up Library
A1: Warm-Up Library
A2: Trigger decides when a drill appears: 'Always', a movement pattern, or a muscle group. Priority decides what survives a tight time budget — 1 is kept first, 8 is dropped first. Phase order decides the order the drills are listed in once selected.
A4: ID | B4: Drill | C4: Övning (SV) | D4: Phase | E4: Phase order | F4: Trigger | G4: Priority | H4: Minutes | I4: How to do it
A5: 1 | B5: Easy cardio | C5: Lätt konditionsarbete | D5: 1 Raise | E5: 1 | F5: Always | G5: 1 | H5: 4 | I5: Bike, row or ski erg at a conversational pace until you break a light sweat.
A6: 2 | B6: Joint circles | C6: Ledcirklar | D6: 2 Mobilise | E6: 2 | F6: Always | G6: 5 | H6: 2 | I6: Ankles, hips, thoracic spine, shoulders. 10 slow circles each direction.
A7: 3 | B7: World's Greatest Stretch | C7: World's greatest stretch | D7: 2 Mobilise | E7: 2 | F7: Always | G7: 4 | H7: 3 | I7: Lunge, elbow to instep, rotate open. 5 per side, no rush.
A8: 4 | B8: Specific ramp-up sets | C8: Uppvärmningsset | D8: 4 Specific | E8: 4 | F8: Always | G8: 2 | H8: 5 | I8: 2–4 progressively heavier sets of your first main lift: roughly 40%, 60%, 80% of the working weight.
A9: 5 | B9: Deep squat hold | C9: Djup knäböjshållning | D9: 2 Mobilise | E9: 2 | F9: Squat | G9: 5 | H9: 2 | I9: Bodyweight or light goblet. Sit in the bottom for 30 s, 3 rounds, gently pushing the knees out.
A10: 6 | B10: Ankle rock-forward | C10: Fotledsrockning | D10: 2 Mobilise | E10: 2 | F10: Squat | G10: 6 | H10: 2 | I10: Half-kneeling, drive the knee forward over the toes. 15 per side.
A11: 7 | B11: Bodyweight squat | C11: Kroppsviktsböj | D11: 3 Activate | E11: 3 | F11: Squat | G11: 3 | H11: 2 | I11: 15 slow reps, pausing 2 s at the bottom of each.
A12: 8 | B12: Banded monster walk | C12: Monster walk med band | D12: 3 Activate | E12: 3 | F12: Squat | G12: 4 | H12: 2 | I12: Band above the knees. 15 steps forward, 15 back, 15 each side.
A13: 9 | B13: Cat-camel | C13: Katt och kamel | D13: 2 Mobilise | E13: 2 | F13: Hinge | G13: 5 | H13: 2 | I13: 10 slow cycles, moving one segment of the spine at a time.
A14: 10 | B14: Glute bridge | C14: Bäckenlyft | D14: 3 Activate | E14: 3 | F14: Hinge | G14: 3 | H14: 2 | I14: 15 reps with a 2 s squeeze at the top. Ribs down.
A15: 11 | B15: Light RDL | C15: Lätt rumänsk marklyft | D15: 3 Activate | E15: 3 | F15: Hinge | G15: 4 | H15: 2 | I15: Empty bar or light kettlebell. 12 reps grooving the hinge pattern.
A16: 12 | B16: 90/90 hip switch | C16: 90/90 höftväxling | D16: 2 Mobilise | E16: 2 | F16: Hinge | G16: 6 | H16: 3 | I16: Seated, rotate both knees side to side. 10 per side, chest tall.
... A53: 49 | B53: Wrist prep | C53: Handledsförberedelse | D53: 2 Mobilise | E53: 2 | F53: Forearms | G53: 8 | H53: 2 | I53: Kneeling wrist rocks, palms down then palms up. 15 each.

Sheet Mobility Library
A1: Mobility Library
A2: Everything here needs a yoga mat and nothing else. Target decides when an exercise is suggested as a cool-down: 'Always', or a muscle group you trained that session. Filter the Target column to build a standalone mobility session on a rest day.
A4: ID | B4: Exercise | C4: Övning (SV) | D4: Type | E4: Type order | F4: Target | G4: Priority | H4: Minutes | I4: How to do it
A5: 1 | B5: Cat-Cow | C5: Katt och ko | D5: Flow | E5: 1 | F5: Always | G5: 1 | H5: 2 | I5: On all fours. Inhale into extension, exhale into flexion. 10 slow cycles.
A6: 2 | B6: Downward Dog | C6: Nedåtgående hund | D6: Flow | E6: 1 | F6: Always | G6: 2 | H6: 2 | I6: Press the floor away, pedal the heels. Hold 60 s, twice.
A7: 3 | B7: Cobra to Child's Pose | C7: Kobra till barnets position | D7: Flow | E7: 1 | F7: Always | G7: 3 | H7: 3 | I7: Flow between the two on the breath. 8 rounds, 5 s in each end position.
A8: 4 | B8: Child's Pose | C8: Barnets position | D8: Wind-down | E8: 5 | F8: Always | G8: 4 | H8: 2 | I8: Knees wide, arms long, forehead down. Breathe into the back ribs for 90 s.
A9: 5 | B9: Legs Up the Wall | C9: Ben upp mot väggen | D9: Wind-down | E9: 5 | F9: Always | G9: 6 | H9: 3 | I9: Hips close to the wall, legs vertical. 3 minutes, nothing else to do.
A10: 6 | B10: Box Breathing | C10: Boxandning | D10: Wind-down | E10: 5 | F10: Always | G10: 7 | H10: 3 | I10: Supine, knees bent. In 4, hold 4, out 4, hold 4. 3 minutes.
A11: 7 | B11: 90/90 Breathing | C11: 90/90-andning | D11: Wind-down | E11: 5 | F11: Always | G11: 6 | H11: 3 | I11: Feet on a wall or a chair, low back flat. 10 slow breaths, ribs down.
A12: 8 | B12: Pigeon Pose | C12: Duvan | D12: Lower body | E12: 2 | F12: Glutes | G12: 2 | H12: 3 | I12: Front shin angled across the mat, hips square. 90 s per side.
A13: 9 | B13: Supine Figure-4 | C13: Liggande figur-4 | D13: Lower body | E13: 2 | F13: Glutes | G13: 2 | H13: 2 | I13: Ankle across the opposite knee, pull the back thigh in. 60 s per side.
A14: 10 | B14: Happy Baby | C14: Glada barnet | D14: Lower body | E14: 2 | F14: Glutes | G14: 4 | H14: 2 | I14: Grab the outsides of the feet, knees toward the armpits. 90 s.
A15: 11 | B15: 90/90 Hip Switch | C15: 90/90 höftväxling | D15: Lower body | E15: 2 | F15: Glutes | G15: 3 | H15: 3 | I15: Rotate the knees side to side without using the hands. 10 per side.
A16: 12 | B16: Half-Kneeling Quad Stretch | C16: Quadstretch i halvknästående | D16: Lower body | E16: 2 | F16: Quads | G16: 2 | H16: 2 | I16: Rear foot lifted, pelvis tucked hard. 60 s per side.
... A47: 43 | B47: Prone Press-Up Breathing | C47: Liggande pressandning | D47: Wind-down | E47: 5 | F47: Core | G47: 4 | H47: 2 | I47: Sphinx position, 10 slow breaths letting the abdomen relax completely.

Sheet Prescriptions
A1: Prescriptions — sets, reps, load, rest and timing by profile and goal
A2: These numbers drive every workout sheet. Columns K–M are used only for the time estimate: how many sets you typically do, how long a set takes, and how long you rest.
A4: Key (do not edit) | B4: Prescription profile | C4: Goal | D4: Sets | E4: Reps | F4: Load | G4: Load min | H4: Load max | I4: Rest | J4: Coaching note | K4: Sets (avg) | L4: Work per set (s) | M4: Rest (avg, s)
A5: =B5&"|"&C5 -> Heavy compound|Explosivity | B5: Heavy compound | C5: Explosivity | D5: 4–6 | E5: 2–3 | F5: 50–70% of 1RM | G5: 0.5 | H5: 0.7 | I5: 2–3 min | J5: Maximal intent every rep. End the set when bar speed drops. | K5: 5 | L5: 12 | M5: 150
A6: =B6&"|"&C6 -> Heavy compound|Strength | B6: Heavy compound | C6: Strength | D6: 3–5 | E6: 3–6 | F6: 80–90% of 1RM | G6: 0.8 | H6: 0.9 | I6: 3–5 min | J6: RPE 7–9. Leave 1–2 reps in reserve on most sets. | K6: 4 | L6: 20 | M6: 240
A7: =B7&"|"&C7 -> Heavy compound|Muscular endurance | B7: Heavy compound | C7: Muscular endurance | D7: 2–4 | E7: 12–20 | F7: 50–65% of 1RM | G7: 0.5 | H7: 0.65 | I7: 45–90 s | J7: Stop 2–3 reps short of failure; keep technique clean. | K7: 3 | L7: 50 | M7: 68
A8: =B8&"|"&C8 -> Compound|Explosivity | B8: Compound | C8: Explosivity | D8: 4–5 | E8: 3–5 | F8: 40–60% of 1RM | G8: 0.4 | H8: 0.6 | I8: 2–3 min | J8: Accelerate through the whole concentric. | K8: 4.5 | L8: 15 | M8: 150
A9: =B9&"|"&C9 -> Compound|Strength | B9: Compound | C9: Strength | D9: 3–4 | E9: 5–8 | F9: 75–85% of 1RM | G9: 0.75 | H9: 0.85 | I9: 2–3 min | J9: RPE 7–9. Add load when the top of the rep range feels easy. | K9: 3.5 | L9: 25 | M9: 150
A10: =B10&"|"&C10 -> Compound|Muscular endurance | B10: Compound | C10: Muscular endurance | D10: 2–4 | E10: 12–20 | F10: 50–60% of 1RM | G10: 0.5 | H10: 0.6 | I10: 45–75 s | J10: Short rest, controlled tempo, no cheating. | K10: 3 | L10: 50 | M10: 60
A11: =B11&"|"&C11 -> Isolation|Explosivity | B11: Isolation | C11: Explosivity | D11: — | E11: — | F11: Not applicable | G11: 0 | H11: 0 | I11: — | J11: Train explosiveness on compound and Olympic lifts instead. | K11: 0 | L11: 0 | M11: 0
A12: =B12&"|"&C12 -> Isolation|Strength | B12: Isolation | C12: Strength | D12: 3–4 | E12: 6–12 | F12: 70–80% of 1RM | G12: 0.7 | H12: 0.8 | I12: 90–120 s | J12: RPE 8–9. Full range of motion beats extra load. | K12: 3.5 | L12: 30 | M12: 105
A13: =B13&"|"&C13 -> Isolation|Muscular endurance | B13: Isolation | C13: Muscular endurance | D13: 2–3 | E13: 15–25 | F13: 40–55% of 1RM | G13: 0.4 | H13: 0.55 | I13: 30–60 s | J13: Strict form; take these close to failure. | K13: 2.5 | L13: 50 | M13: 45
A14: =B14&"|"&C14 -> Olympic lift|Explosivity | B14: Olympic lift | C14: Explosivity | D14: 5–8 | E14: 1–3 | F14: 70–85% of 1RM | G14: 0.7 | H14: 0.85 | I14: 2–3 min | J14: Quality over quantity. End the session when technique slips. | K14: 6.5 | L14: 10 | M14: 150
A15: =B15&"|"&C15 -> Olympic lift|Strength | B15: Olympic lift | C15: Strength | D15: 4–6 | E15: 2–3 | F15: 85–92% of 1RM | G15: 0.85 | H15: 0.92 | I15: 3–4 min | J15: Heavy singles and doubles; only with solid technique. | K15: 5 | L15: 8 | M15: 210
A16: =B16&"|"&C16 -> Olympic lift|Muscular endurance | B16: Olympic lift | C16: Muscular endurance | D16: 3–5 | E16: 6–10 | F16: 55–65% of 1RM | G16: 0.55 | H16: 0.65 | I16: 60–90 s | J16: Complexes only. Stop the moment form degrades. | K16: 4 | L16: 25 | M16: 75
... A25: =B25&"|"&C25 -> Carry|Muscular endurance | B25: Carry | C25: Muscular endurance | D25: 2–4 | E25: 60–100 m | F25: 40–55% of max carry | G25: 0.4 | H25: 0.55 | I25: 60–90 s | J25: Long unbroken distance. | K25: 3 | L25: 60 | M25: 75
A27: Time assumptions
A28: Set-up and transition per exercise (seconds) | D28: 90 | E28: Walking over, loading the bar, adjusting the machine. Raise it for a busy gym.

Sheet Workout A
A1: Workout Builder — Workout A
A3: Workout name | B3: Lower body — heavy | D3: Pick your main exercises first (they drive the warm-up and cool-down), then set the goal and the time budgets.
A4: Date
A5: Goal | B5: Strength
A6: Warm-up budget (min) | B6: 15
A7: Cool-down budget (min) | B7: 8
A8: Session note | B8: Bar speed felt good, add 2.5 kg next week
A10: WARM-UP — builds itself from the movement patterns and muscles below
A11: # | B11: Drill | C11: Phase | D11: Triggered by | E11: Min | F11: How to do it
A12: 1 | B12: =IFERROR(INDEX(WuName,MATCH(1,$AD$12:$AD$60,0)),"") -> Easy cardio | C12: =IF($B12="","",INDEX(WuPhase,MATCH(1,$AD$12:$AD$60,0))) -> 1 Raise | D12: =IF($B12="","",INDEX(WuTrigger,MATCH(1,$AD$12:$AD$60,0))) -> Always | E12: =IF($B12="","",INDEX(WuMin,MATCH(1,$AD$12:$AD$60,0))) -> 4 | F12: =IF($B12="","",INDEX(WuHow,MATCH(1,$AD$12:$AD$60,0))) -> Bike, row or ski erg at a conversational pace until you break a light sweat. | Y12: =IF(OR(INDEX(WuTrigger,1)="Always",COUNTIF($D$30:$D$51,INDEX(WuTrigger,1))>0,COUNTIF($E$30:$E$51,INDEX(WuTrigger,1))>0),1,0) -> 1 | Z12: =INDEX(WuPriority,1)*1000+1 -> 1001 | AA12: =IF($Y12=0,"",SUMIFS(WuMin,$Y$12:$Y$60,1,$Z$12:$Z$60,"<="&$Z12)) -> 4 | AB12: =IF(AND($Y12=1,$AA12<=$B$6),1,0) -> 1 | AC12: =INDEX(WuPhaseN,1)*1000+1 -> 1001 | AD12: =IF($AB12=0,"",COUNTIFS($AB$12:$AB$60,1,$AC$12:$AC$60,"<"&$AC12)+1) -> 1 | AF12: =IF(OR(INDEX(MoTarget,1)="Always",COUNTIF($E$30:$E$51,INDEX(MoTarget,1))>0,COUNTIF($F$30:$F$51,"*"&INDEX(MoTarget,1)&"*")>0),1,0) -> 1 | AG12: =INDEX(MoPriority,1)*1000+1 -> 1001 | AH12: =IF($AF12=0,"",SUMIFS(MoMin,$AF$12:$AF$54,1,$AG$12:$AG$54,"<="&$AG12)) -> 2 | AI12: =IF(AND($AF12=1,$AH12<=$B$7),1,0) -> 1 | AJ12: =INDEX(MoTypeN,1)*1000+1 -> 1001 | AK12: =IF($AI12=0,"",COUNTIFS($AI$12:$AI$54,1,$AJ$12:$AJ$54,"<"&$AJ12)+1) -> 1
A13: 2 | B13: =IFERROR(INDEX(WuName,MATCH(2,$AD$12:$AD$60,0)),"") -> Bodyweight squat | C13: =IF($B13="","",INDEX(WuPhase,MATCH(2,$AD$12:$AD$60,0))) -> 3 Activate | D13: =IF($B13="","",INDEX(WuTrigger,MATCH(2,$AD$12:$AD$60,0))) -> Squat | E13: =IF($B13="","",INDEX(WuMin,MATCH(2,$AD$12:$AD$60,0))) -> 2 | F13: =IF($B13="","",INDEX(WuHow,MATCH(2,$AD$12:$AD$60,0))) -> 15 slow reps, pausing 2 s at the bottom of each. | Y13: =IF(OR(INDEX(WuTrigger,2)="Always",COUNTIF($D$30:$D$51,INDEX(WuTrigger,2))>0,COUNTIF($E$30:$E$51,INDEX(WuTrigger,2))>0),1,0) -> 1 | Z13: =INDEX(WuPriority,2)*1000+2 -> 5002 | AA13: =IF($Y13=0,"",SUMIFS(WuMin,$Y$12:$Y$60,1,$Z$12:$Z$60,"<="&$Z13)) -> 30 | AB13: =IF(AND($Y13=1,$AA13<=$B$6),1,0) -> 0 | AC13: =INDEX(WuPhaseN,2)*1000+2 -> 2002 | AD13: =IF($AB13=0,"",COUNTIFS($AB$12:$AB$60,1,$AC$12:$AC$60,"<"&$AC13)+1) | AF13: =IF(OR(INDEX(MoTarget,2)="Always",COUNTIF($E$30:$E$51,INDEX(MoTarget,2))>0,COUNTIF($F$30:$F$51,"*"&INDEX(MoTarget,2)&"*")>0),1,0) -> 1 | AG13: =INDEX(MoPriority,2)*1000+2 -> 2002 | AH13: =IF($AF13=0,"",SUMIFS(MoMin,$AF$12:$AF$54,1,$AG$12:$AG$54,"<="&$AG13)) -> 4 | AI13: =IF(AND($AF13=1,$AH13<=$B$7),1,0) -> 1 | AJ13: =INDEX(MoTypeN,2)*1000+2 -> 1002 | AK13: =IF($AI13=0,"",COUNTIFS($AI$12:$AI$54,1,$AJ$12:$AJ$54,"<"&$AJ13)+1) -> 2
A14: 3 | B14: =IFERROR(INDEX(WuName,MATCH(3,$AD$12:$AD$60,0)),"") -> Glute bridge | C14: =IF($B14="","",INDEX(WuPhase,MATCH(3,$AD$12:$AD$60,0))) -> 3 Activate | D14: =IF($B14="","",INDEX(WuTrigger,MATCH(3,$AD$12:$AD$60,0))) -> Hinge | E14: =IF($B14="","",INDEX(WuMin,MATCH(3,$AD$12:$AD$60,0))) -> 2 | F14: =IF($B14="","",INDEX(WuHow,MATCH(3,$AD$12:$AD$60,0))) -> 15 reps with a 2 s squeeze at the top. Ribs down. | Y14: =IF(OR(INDEX(WuTrigger,3)="Always",COUNTIF($D$30:$D$51,INDEX(WuTrigger,3))>0,COUNTIF($E$30:$E$51,INDEX(WuTrigger,3))>0),1,0) -> 1 | Z14: =INDEX(WuPriority,3)*1000+3 -> 4003 | AA14: =IF($Y14=0,"",SUMIFS(WuMin,$Y$12:$Y$60,1,$Z$12:$Z$60,"<="&$Z14)) -> 16 | AB14: =IF(AND($Y14=1,$AA14<=$B$6),1,0) -> 0 | AC14: =INDEX(WuPhaseN,3)*1000+3 -> 2003 | AD14: =IF($AB14=0,"",COUNTIFS($AB$12:$AB$60,1,$AC$12:$AC$60,"<"&$AC14)+1) | AF14: =IF(OR(INDEX(MoTarget,3)="Always",COUNTIF($E$30:$E$51,INDEX(MoTarget,3))>0,COUNTIF($F$30:$F$51,"*"&INDEX(MoTarget,3)&"*")>0),1,0) -> 1 | AG14: =INDEX(MoPriority,3)*1000+3 -> 3003 | AH14: =IF($AF14=0,"",SUMIFS(MoMin,$AF$12:$AF$54,1,$AG$12:$AG$54,"<="&$AG14)) -> 29 | AI14: =IF(AND($AF14=1,$AH14<=$B$7),1,0) -> 0 | AJ14: =INDEX(MoTypeN,3)*1000+3 -> 1003 | AK14: =IF($AI14=0,"",COUNTIFS($AI$12:$AI$54,1,$AJ$12:$AJ$54,"<"&$AJ14)+1)
A15: 4 | B15: =IFERROR(INDEX(WuName,MATCH(4,$AD$12:$AD$60,0)),"") -> Specific ramp-up sets | C15: =IF($B15="","",INDEX(WuPhase,MATCH(4,$AD$12:$AD$60,0))) -> 4 Specific | D15: =IF($B15="","",INDEX(WuTrigger,MATCH(4,$AD$12:$AD$60,0))) -> Always | E15: =IF($B15="","",INDEX(WuMin,MATCH(4,$AD$12:$AD$60,0))) -> 5 | F15: =IF($B15="","",INDEX(WuHow,MATCH(4,$AD$12:$AD$60,0))) -> 2–4 progressively heavier sets of your first main lift: roughly 40%, 60%, 80% of the working weight. | Y15: =IF(OR(INDEX(WuTrigger,4)="Always",COUNTIF($D$30:$D$51,INDEX(WuTrigger,4))>0,COUNTIF($E$30:$E$51,INDEX(WuTrigger,4))>0),1,0) -> 1 | Z15: =INDEX(WuPriority,4)*1000+4 -> 2004 | AA15: =IF($Y15=0,"",SUMIFS(WuMin,$Y$12:$Y$60,1,$Z$12:$Z$60,"<="&$Z15)) -> 9 | AB15: =IF(AND($Y15=1,$AA15<=$B$6),1,0) -> 1 | AC15: =INDEX(WuPhaseN,4)*1000+4 -> 4004 | AD15: =IF($AB15=0,"",COUNTIFS($AB$12:$AB$60,1,$AC$12:$AC$60,"<"&$AC15)+1) -> 4 | AF15: =IF(OR(INDEX(MoTarget,4)="Always",COUNTIF($E$30:$E$51,INDEX(MoTarget,4))>0,COUNTIF($F$30:$F$51,"*"&INDEX(MoTarget,4)&"*")>0),1,0) -> 1 | AG15: =INDEX(MoPriority,4)*1000+4 -> 4004 | AH15: =IF($AF15=0,"",SUMIFS(MoMin,$AF$12:$AF$54,1,$AG$12:$AG$54,"<="&$AG15)) -> 52 | AI15: =IF(AND($AF15=1,$AH15<=$B$7),1,0) -> 0 | AJ15: =INDEX(MoTypeN,4)*1000+4 -> 5004 | AK15: =IF($AI15=0,"",COUNTIFS($AI$12:$AI$54,1,$AJ$12:$AJ$54,"<"&$AJ15)+1)
A16: 5 | B16: =IFERROR(INDEX(WuName,MATCH(5,$AD$12:$AD$60,0)),"") | C16: =IF($B16="","",INDEX(WuPhase,MATCH(5,$AD$12:$AD$60,0))) | D16: =IF($B16="","",INDEX(WuTrigger,MATCH(5,$AD$12:$AD$60,0))) | E16: =IF($B16="","",INDEX(WuMin,MATCH(5,$AD$12:$AD$60,0))) | F16: =IF($B16="","",INDEX(WuHow,MATCH(5,$AD$12:$AD$60,0))) | Y16: =IF(OR(INDEX(WuTrigger,5)="Always",COUNTIF($D$30:$D$51,INDEX(WuTrigger,5))>0,COUNTIF($E$30:$E$51,INDEX(WuTrigger,5))>0),1,0) -> 1 | Z16: =INDEX(WuPriority,5)*1000+5 -> 5005 | AA16: =IF($Y16=0,"",SUMIFS(WuMin,$Y$12:$Y$60,1,$Z$12:$Z$60,"<="&$Z16)) -> 32 | AB16: =IF(AND($Y16=1,$AA16<=$B$6),1,0) -> 0 | AC16: =INDEX(WuPhaseN,5)*1000+5 -> 2005 | AD16: =IF($AB16=0,"",COUNTIFS($AB$12:$AB$60,1,$AC$12:$AC$60,"<"&$AC16)+1) | AF16: =IF(OR(INDEX(MoTarget,5)="Always",COUNTIF($E$30:$E$51,INDEX(MoTarget,5))>0,COUNTIF($F$30:$F$51,"*"&INDEX(MoTarget,5)&"*")>0),1,0) -> 1 | AG16: =INDEX(MoPriority,5)*1000+5 -> 6005 | AH16: =IF($AF16=0,"",SUMIFS(MoMin,$AF$12:$AF$54,1,$AG$12:$AG$54,"<="&$AG16)) -> 73 | AI16: =IF(AND($AF16=1,$AH16<=$B$7),1,0) -> 0 | AJ16: =INDEX(MoTypeN,5)*1000+5 -> 5005 | AK16: =IF($AI16=0,"",COUNTIFS($AI$12:$AI$54,1,$AJ$12:$AJ$54,"<"&$AJ16)+1)
A17: 6 | B17: =IFERROR(INDEX(WuName,MATCH(6,$AD$12:$AD$60,0)),"") | C17: =IF($B17="","",INDEX(WuPhase,MATCH(6,$AD$12:$AD$60,0))) | D17: =IF($B17="","",INDEX(WuTrigger,MATCH(6,$AD$12:$AD$60,0))) | E17: =IF($B17="","",INDEX(WuMin,MATCH(6,$AD$12:$AD$60,0))) | F17: =IF($B17="","",INDEX(WuHow,MATCH(6,$AD$12:$AD$60,0))) | Y17: =IF(OR(INDEX(WuTrigger,6)="Always",COUNTIF($D$30:$D$51,INDEX(WuTrigger,6))>0,COUNTIF($E$30:$E$51,INDEX(WuTrigger,6))>0),1,0) -> 1 | Z17: =INDEX(WuPriority,6)*1000+6 -> 6006 | AA17: =IF($Y17=0,"",SUMIFS(WuMin,$Y$12:$Y$60,1,$Z$12:$Z$60,"<="&$Z17)) -> 40 | AB17: =IF(AND($Y17=1,$AA17<=$B$6),1,0) -> 0 | AC17: =INDEX(WuPhaseN,6)*1000+6 -> 2006 | AD17: =IF($AB17=0,"",COUNTIFS($AB$12:$AB$60,1,$AC$12:$AC$60,"<"&$AC17)+1) | AF17: =IF(OR(INDEX(MoTarget,6)="Always",COUNTIF($E$30:$E$51,INDEX(MoTarget,6))>0,COUNTIF($F$30:$F$51,"*"&INDEX(MoTarget,6)&"*")>0),1,0) -> 1 | AG17: =INDEX(MoPriority,6)*1000+6 -> 7006 | AH17: =IF($AF17=0,"",SUMIFS(MoMin,$AF$12:$AF$54,1,$AG$12:$AG$54,"<="&$AG17)) -> 79 | AI17: =IF(AND($AF17=1,$AH17<=$B$7),1,0) -> 0 | AJ17: =INDEX(MoTypeN,6)*1000+6 -> 5006 | AK17: =IF($AI17=0,"",COUNTIFS($AI$12:$AI$54,1,$AJ$12:$AJ$54,"<"&$AJ17)+1)
A18: 7 | B18: =IFERROR(INDEX(WuName,MATCH(7,$AD$12:$AD$60,0)),"") | C18: =IF($B18="","",INDEX(WuPhase,MATCH(7,$AD$12:$AD$60,0))) | D18: =IF($B18="","",INDEX(WuTrigger,MATCH(7,$AD$12:$AD$60,0))) | E18: =IF($B18="","",INDEX(WuMin,MATCH(7,$AD$12:$AD$60,0))) | F18: =IF($B18="","",INDEX(WuHow,MATCH(7,$AD$12:$AD$60,0))) | Y18: =IF(OR(INDEX(WuTrigger,7)="Always",COUNTIF($D$30:$D$51,INDEX(WuTrigger,7))>0,COUNTIF($E$30:$E$51,INDEX(WuTrigger,7))>0),1,0) -> 1 | Z18: =INDEX(WuPriority,7)*1000+7 -> 3007 | AA18: =IF($Y18=0,"",SUMIFS(WuMin,$Y$12:$Y$60,1,$Z$12:$Z$60,"<="&$Z18)) -> 11 | AB18: =IF(AND($Y18=1,$AA18<=$B$6),1,0) -> 1 | AC18: =INDEX(WuPhaseN,7)*1000+7 -> 3007 | AD18: =IF($AB18=0,"",COUNTIFS($AB$12:$AB$60,1,$AC$12:$AC$60,"<"&$AC18)+1) -> 2 | AF18: =IF(OR(INDEX(MoTarget,7)="Always",COUNTIF($E$30:$E$51,INDEX(MoTarget,7))>0,COUNTIF($F$30:$F$51,"*"&INDEX(MoTarget,7)&"*")>0),1,0) -> 1 | AG18: =INDEX(MoPriority,7)*1000+7 -> 6007 | AH18: =IF($AF18=0,"",SUMIFS(MoMin,$AF$12:$AF$54,1,$AG$12:$AG$54,"<="&$AG18)) -> 76 | AI18: =IF(AND($AF18=1,$AH18<=$B$7),1,0) -> 0 | AJ18: =INDEX(MoTypeN,7)*1000+7 -> 5007 | AK18: =IF($AI18=0,"",COUNTIFS($AI$12:$AI$54,1,$AJ$12:$AJ$54,"<"&$AJ18)+1)
A19: 8 | B19: =IFERROR(INDEX(WuName,MATCH(8,$AD$12:$AD$60,0)),"") | C19: =IF($B19="","",INDEX(WuPhase,MATCH(8,$AD$12:$AD$60,0))) | D19: =IF($B19="","",INDEX(WuTrigger,MATCH(8,$AD$12:$AD$60,0))) | E19: =IF($B19="","",INDEX(WuMin,MATCH(8,$AD$12:$AD$60,0))) | F19: =IF($B19="","",INDEX(WuHow,MATCH(8,$AD$12:$AD$60,0))) | Y19: =IF(OR(INDEX(WuTrigger,8)="Always",COUNTIF($D$30:$D$51,INDEX(WuTrigger,8))>0,COUNTIF($E$30:$E$51,INDEX(WuTrigger,8))>0),1,0) -> 1 | Z19: =INDEX(WuPriority,8)*1000+8 -> 4008 | AA19: =IF($Y19=0,"",SUMIFS(WuMin,$Y$12:$Y$60,1,$Z$12:$Z$60,"<="&$Z19)) -> 18 | AB19: =IF(AND($Y19=1,$AA19<=$B$6),1,0) -> 0 | AC19: =INDEX(WuPhaseN,8)*1000+8 -> 3008 | AD19: =IF($AB19=0,"",COUNTIFS($AB$12:$AB$60,1,$AC$12:$AC$60,"<"&$AC19)+1) | AF19: =IF(OR(INDEX(MoTarget,8)="Always",COUNTIF($E$30:$E$51,INDEX(MoTarget,8))>0,COUNTIF($F$30:$F$51,"*"&INDEX(MoTarget,8)&"*")>0),1,0) -> 1 | AG19: =INDEX(MoPriority,8)*1000+8 -> 2008 | AH19: =IF($AF19=0,"",SUMIFS(MoMin,$AF$12:$AF$54,1,$AG$12:$AG$54,"<="&$AG19)) -> 7 | AI19: =IF(AND($AF19=1,$AH19<=$B$7),1,0) -> 1 | AJ19: =INDEX(MoTypeN,8)*1000+8 -> 2008 | AK19: =IF($AI19=0,"",COUNTIFS($AI$12:$AI$54,1,$AJ$12:$AJ$54,"<"&$AJ19)+1) -> 3
A20: 9 | B20: =IFERROR(INDEX(WuName,MATCH(9,$AD$12:$AD$60,0)),"") | C20: =IF($B20="","",INDEX(WuPhase,MATCH(9,$AD$12:$AD$60,0))) | D20: =IF($B20="","",INDEX(WuTrigger,MATCH(9,$AD$12:$AD$60,0))) | E20: =IF($B20="","",INDEX(WuMin,MATCH(9,$AD$12:$AD$60,0))) | F20: =IF($B20="","",INDEX(WuHow,MATCH(9,$AD$12:$AD$60,0))) | Y20: =IF(OR(INDEX(WuTrigger,9)="Always",COUNTIF($D$30:$D$51,INDEX(WuTrigger,9))>0,COUNTIF($E$30:$E$51,INDEX(WuTrigger,9))>0),1,0) -> 1 | Z20: =INDEX(WuPriority,9)*1000+9 -> 5009 | AA20: =IF($Y20=0,"",SUMIFS(WuMin,$Y$12:$Y$60,1,$Z$12:$Z$60,"<="&$Z20)) -> 34 | AB20: =IF(AND($Y20=1,$AA20<=$B$6),1,0) -> 0 | AC20: =INDEX(WuPhaseN,9)*1000+9 -> 2009 | AD20: =IF($AB20=0,"",COUNTIFS($AB$12:$AB$60,1,$AC$12:$AC$60,"<"&$AC20)+1) | AF20: =IF(OR(INDEX(MoTarget,9)="Always",COUNTIF($E$30:$E$51,INDEX(MoTarget,9))>0,COUNTIF($F$30:$F$51,"*"&INDEX(MoTarget,9)&"*")>0),1,0) -> 1 | AG20: =INDEX(MoPriority,9)*1000+9 -> 2009 | AH20: =IF($AF20=0,"",SUMIFS(MoMin,$AF$12:$AF$54,1,$AG$12:$AG$54,"<="&$AG20)) -> 9 | AI20: =IF(AND($AF20=1,$AH20<=$B$7),1,0) -> 0 | AJ20: =INDEX(MoTypeN,9)*1000+9 -> 2009 | AK20: =IF($AI20=0,"",COUNTIFS($AI$12:$AI$54,1,$AJ$12:$AJ$54,"<"&$AJ20)+1)
A21: 10 | B21: =IFERROR(INDEX(WuName,MATCH(10,$AD$12:$AD$60,0)),"") | C21: =IF($B21="","",INDEX(WuPhase,MATCH(10,$AD$12:$AD$60,0))) | D21: =IF($B21="","",INDEX(WuTrigger,MATCH(10,$AD$12:$AD$60,0))) | E21: =IF($B21="","",INDEX(WuMin,MATCH(10,$AD$12:$AD$60,0))) | F21: =IF($B21="","",INDEX(WuHow,MATCH(10,$AD$12:$AD$60,0))) | Y21: =IF(OR(INDEX(WuTrigger,10)="Always",COUNTIF($D$30:$D$51,INDEX(WuTrigger,10))>0,COUNTIF($E$30:$E$51,INDEX(WuTrigger,10))>0),1,0) -> 1 | Z21: =INDEX(WuPriority,10)*1000+10 -> 3010 | AA21: =IF($Y21=0,"",SUMIFS(WuMin,$Y$12:$Y$60,1,$Z$12:$Z$60,"<="&$Z21)) -> 13 | AB21: =IF(AND($Y21=1,$AA21<=$B$6),1,0) -> 1 | AC21: =INDEX(WuPhaseN,10)*1000+10 -> 3010 | AD21: =IF($AB21=0,"",COUNTIFS($AB$12:$AB$60,1,$AC$12:$AC$60,"<"&$AC21)+1) -> 3 | AF21: =IF(OR(INDEX(MoTarget,10)="Always",COUNTIF($E$30:$E$51,INDEX(MoTarget,10))>0,COUNTIF($F$30:$F$51,"*"&INDEX(MoTarget,10)&"*")>0),1,0) -> 1 | AG21: =INDEX(MoPriority,10)*1000+10 -> 4010 | AH21: =IF($AF21=0,"",SUMIFS(MoMin,$AF$12:$AF$54,1,$AG$12:$AG$54,"<="&$AG21)) -> 54 | AI21: =IF(AND($AF21=1,$AH21<=$B$7),1,0) -> 0 | AJ21: =INDEX(MoTypeN,10)*1000+10 -> 2010 | AK21: =IF($AI21=0,"",COUNTIFS($AI$12:$AI$54,1,$AJ$12:$AJ$54,"<"&$AJ21)+1)
A22: 11 | B22: =IFERROR(INDEX(WuName,MATCH(11,$AD$12:$AD$60,0)),"") | C22: =IF($B22="","",INDEX(WuPhase,MATCH(11,$AD$12:$AD$60,0))) | D22: =IF($B22="","",INDEX(WuTrigger,MATCH(11,$AD$12:$AD$60,0))) | E22: =IF($B22="","",INDEX(WuMin,MATCH(11,$AD$12:$AD$60,0))) | F22: =IF($B22="","",INDEX(WuHow,MATCH(11,$AD$12:$AD$60,0))) | Y22: =IF(OR(INDEX(WuTrigger,11)="Always",COUNTIF($D$30:$D$51,INDEX(WuTrigger,11))>0,COUNTIF($E$30:$E$51,INDEX(WuTrigger,11))>0),1,0) -> 1 | Z22: =INDEX(WuPriority,11)*1000+11 -> 4011 | AA22: =IF($Y22=0,"",SUMIFS(WuMin,$Y$12:$Y$60,1,$Z$12:$Z$60,"<="&$Z22)) -> 20 | AB22: =IF(AND($Y22=1,$AA22<=$B$6),1,0) -> 0 | AC22: =INDEX(WuPhaseN,11)*1000+11 -> 3011 | AD22: =IF($AB22=0,"",COUNTIFS($AB$12:$AB$60,1,$AC$12:$AC$60,"<"&$AC22)+1) | AF22: =IF(OR(INDEX(MoTarget,11)="Always",COUNTIF($E$30:$E$51,INDEX(MoTarget,11))>0,COUNTIF($F$30:$F$51,"*"&INDEX(MoTarget,11)&"*")>0),1,0) -> 1 | AG22: =INDEX(MoPriority,11)*1000+11 -> 3011 | AH22: =IF($AF22=0,"",SUMIFS(MoMin,$AF$12:$AF$54,1,$AG$12:$AG$54,"<="&$AG22)) -> 32 | AI22: =IF(AND($AF22=1,$AH22<=$B$7),1,0) -> 0 | AJ22: =INDEX(MoTypeN,11)*1000+11 -> 2011 | AK22: =IF($AI22=0,"",COUNTIFS($AI$12:$AI$54,1,$AJ$12:$AJ$54,"<"&$AJ22)+1)
A23: 12 | B23: =IFERROR(INDEX(WuName,MATCH(12,$AD$12:$AD$60,0)),"") | C23: =IF($B23="","",INDEX(WuPhase,MATCH(12,$AD$12:$AD$60,0))) | D23: =IF($B23="","",INDEX(WuTrigger,MATCH(12,$AD$12:$AD$60,0))) | E23: =IF($B23="","",INDEX(WuMin,MATCH(12,$AD$12:$AD$60,0))) | F23: =IF($B23="","",INDEX(WuHow,MATCH(12,$AD$12:$AD$60,0))) | Y23: =IF(OR(INDEX(WuTrigger,12)="Always",COUNTIF($D$30:$D$51,INDEX(WuTrigger,12))>0,COUNTIF($E$30:$E$51,INDEX(WuTrigger,12))>0),1,0) -> 1 | Z23: =INDEX(WuPriority,12)*1000+12 -> 6012 | AA23: =IF($Y23=0,"",SUMIFS(WuMin,$Y$12:$Y$60,1,$Z$12:$Z$60,"<="&$Z23)) -> 43 | AB23: =IF(AND($Y23=1,$AA23<=$B$6),1,0) -> 0 | AC23: =INDEX(WuPhaseN,12)*1000+12 -> 2012 | AD23: =IF($AB23=0,"",COUNTIFS($AB$12:$AB$60,1,$AC$12:$AC$60,"<"&$AC23)+1) | AF23: =IF(OR(INDEX(MoTarget,12)="Always",COUNTIF($E$30:$E$51,INDEX(MoTarget,12))>0,COUNTIF($F$30:$F$51,"*"&INDEX(MoTarget,12)&"*")>0),1,0) -> 1 | AG23: =INDEX(MoPriority,12)*1000+12 -> 2012 | AH23: =IF($AF23=0,"",SUMIFS(MoMin,$AF$12:$AF$54,1,$AG$12:$AG$54,"<="&$AG23)) -> 11 | AI23: =IF(AND($AF23=1,$AH23<=$B$7),1,0) -> 0 | AJ23: =INDEX(MoTypeN,12)*1000+12 -> 2012 | AK23: =IF($AI23=0,"",COUNTIFS($AI$12:$AI$54,1,$AJ$12:$AJ$54,"<"&$AJ23)+1)
A24: 13 | B24: =IFERROR(INDEX(WuName,MATCH(13,$AD$12:$AD$60,0)),"") | C24: =IF($B24="","",INDEX(WuPhase,MATCH(13,$AD$12:$AD$60,0))) | D24: =IF($B24="","",INDEX(WuTrigger,MATCH(13,$AD$12:$AD$60,0))) | E24: =IF($B24="","",INDEX(WuMin,MATCH(13,$AD$12:$AD$60,0))) | F24: =IF($B24="","",INDEX(WuHow,MATCH(13,$AD$12:$AD$60,0))) | Y24: =IF(OR(INDEX(WuTrigger,13)="Always",COUNTIF($D$30:$D$51,INDEX(WuTrigger,13))>0,COUNTIF($E$30:$E$51,INDEX(WuTrigger,13))>0),1,0) -> 1 | Z24: =INDEX(WuPriority,13)*1000+13 -> 5013 | AA24: =IF($Y24=0,"",SUMIFS(WuMin,$Y$12:$Y$60,1,$Z$12:$Z$60,"<="&$Z24)) -> 36 | AB24: =IF(AND($Y24=1,$AA24<=$B$6),1,0) -> 0 | AC24: =INDEX(WuPhaseN,13)*1000+13 -> 2013 | AD24: =IF($AB24=0,"",COUNTIFS($AB$12:$AB$60,1,$AC$12:$AC$60,"<"&$AC24)+1) | AF24: =IF(OR(INDEX(MoTarget,13)="Always",COUNTIF($E$30:$E$51,INDEX(MoTarget,13))>0,COUNTIF($F$30:$F$51,"*"&INDEX(MoTarget,13)&"*")>0),1,0) -> 1 | AG24: =INDEX(MoPriority,13)*1000+13 -> 3013 | AH24: =IF($AF24=0,"",SUMIFS(MoMin,$AF$12:$AF$54,1,$AG$12:$AG$54,"<="&$AG24)) -> 35 | AI24: =IF(AND($AF24=1,$AH24<=$B$7),1,0) -> 0 | AJ24: =INDEX(MoTypeN,13)*1000+13 -> 2013 | AK24: =IF($AI24=0,"",COUNTIFS($AI$12:$AI$54,1,$AJ$12:$AJ$54,"<"&$AJ24)+1)
A25: 14 | B25: =IFERROR(INDEX(WuName,MATCH(14,$AD$12:$AD$60,0)),"") | C25: =IF($B25="","",INDEX(WuPhase,MATCH(14,$AD$12:$AD$60,0))) | D25: =IF($B25="","",INDEX(WuTrigger,MATCH(14,$AD$12:$AD$60,0))) | E25: =IF($B25="","",INDEX(WuMin,MATCH(14,$AD$12:$AD$60,0))) | F25: =IF($B25="","",INDEX(WuHow,MATCH(14,$AD$12:$AD$60,0))) | Y25: =IF(OR(INDEX(WuTrigger,14)="Always",COUNTIF($D$30:$D$51,INDEX(WuTrigger,14))>0,COUNTIF($E$30:$E$51,INDEX(WuTrigger,14))>0),1,0) -> 1 | Z25: =INDEX(WuPriority,14)*1000+14 -> 4014 | AA25: =IF($Y25=0,"",SUMIFS(WuMin,$Y$12:$Y$60,1,$Z$12:$Z$60,"<="&$Z25)) -> 22 | AB25: =IF(AND($Y25=1,$AA25<=$B$6),1,0) -> 0 | AC25: =INDEX(WuPhaseN,14)*1000+14 -> 3014 | AD25: =IF($AB25=0,"",COUNTIFS($AB$12:$AB$60,1,$AC$12:$AC$60,"<"&$AC25)+1) | AF25: =IF(OR(INDEX(MoTarget,14)="Always",COUNTIF($E$30:$E$51,INDEX(MoTarget,14))>0,COUNTIF($F$30:$F$51,"*"&INDEX(MoTarget,14)&"*")>0),1,0) -> 1 | AG25: =INDEX(MoPriority,14)*1000+14 -> 4014 | AH25: =IF($AF25=0,"",SUMIFS(MoMin,$AF$12:$AF$54,1,$AG$12:$AG$54,"<="&$AG25)) -> 56 | AI25: =IF(AND($AF25=1,$AH25<=$B$7),1,0) -> 0 | AJ25: =INDEX(MoTypeN,14)*1000+14 -> 2014 | AK25: =IF($AI25=0,"",COUNTIFS($AI$12:$AI$54,1,$AJ$12:$AJ$54,"<"&$AJ25)+1)
A26: Warm-up total (min) | E26: =SUMIFS(WuMin,$AB$12:$AB$60,1) -> 13 | Y26: =IF(OR(INDEX(WuTrigger,15)="Always",COUNTIF($D$30:$D$51,INDEX(WuTrigger,15))>0,COUNTIF($E$30:$E$51,INDEX(WuTrigger,15))>0),1,0) -> 1 | Z26: =INDEX(WuPriority,15)*1000+15 -> 6015 | AA26: =IF($Y26=0,"",SUMIFS(WuMin,$Y$12:$Y$60,1,$Z$12:$Z$60,"<="&$Z26)) -> 45 | AB26: =IF(AND($Y26=1,$AA26<=$B$6),1,0) -> 0 | AC26: =INDEX(WuPhaseN,15)*1000+15 -> 3015 | AD26: =IF($AB26=0,"",COUNTIFS($AB$12:$AB$60,1,$AC$12:$AC$60,"<"&$AC26)+1) | AF26: =IF(OR(INDEX(MoTarget,15)="Always",COUNTIF($E$30:$E$51,INDEX(MoTarget,15))>0,COUNTIF($F$30:$F$51,"*"&INDEX(MoTarget,15)&"*")>0),1,0) -> 1 | AG26: =INDEX(MoPriority,15)*1000+15 -> 2015 | AH26: =IF($AF26=0,"",SUMIFS(MoMin,$AF$12:$AF$54,1,$AG$12:$AG$54,"<="&$AG26)) -> 13 | AI26: =IF(AND($AF26=1,$AH26<=$B$7),1,0) -> 0 | AJ26: =INDEX(MoTypeN,15)*1000+15 -> 2015 | AK26: =IF($AI26=0,"",COUNTIFS($AI$12:$AI$54,1,$AJ$12:$AJ$54,"<"&$AJ26)+1)
Y27: =IF(OR(INDEX(WuTrigger,16)="Always",COUNTIF($D$30:$D$51,INDEX(WuTrigger,16))>0,COUNTIF($E$30:$E$51,INDEX(WuTrigger,16))>0),1,0) -> 0 | Z27: =INDEX(WuPriority,16)*1000+16 -> 3016 | AA27: =IF($Y27=0,"",SUMIFS(WuMin,$Y$12:$Y$60,1,$Z$12:$Z$60,"<="&$Z27)) | AB27: =IF(AND($Y27=1,$AA27<=$B$6),1,0) -> 0 | AC27: =INDEX(WuPhaseN,16)*1000+16 -> 3016 | AD27: =IF($AB27=0,"",COUNTIFS($AB$12:$AB$60,1,$AC$12:$AC$60,"<"&$AC27)+1) | AF27: =IF(OR(INDEX(MoTarget,16)="Always",COUNTIF($E$30:$E$51,INDEX(MoTarget,16))>0,COUNTIF($F$30:$F$51,"*"&INDEX(MoTarget,16)&"*")>0),1,0) -> 1 | AG27: =INDEX(MoPriority,16)*1000+16 -> 2016 | AH27: =IF($AF27=0,"",SUMIFS(MoMin,$AF$12:$AF$54,1,$AG$12:$AG$54,"<="&$AG27)) -> 16 | AI27: =IF(AND($AF27=1,$AH27<=$B$7),1,0) -> 0 | AJ27: =INDEX(MoTypeN,16)*1000+16 -> 2016 | AK27: =IF($AI27=0,"",COUNTIFS($AI$12:$AI$54,1,$AJ$12:$AJ$54,"<"&$AJ27)+1)
A28: MAIN SESSION | Y28: =IF(OR(INDEX(WuTrigger,17)="Always",COUNTIF($D$30:$D$51,INDEX(WuTrigger,17))>0,COUNTIF($E$30:$E$51,INDEX(WuTrigger,17))>0),1,0) -> 0 | Z28: =INDEX(WuPriority,17)*1000+17 -> 3017 | AA28: =IF($Y28=0,"",SUMIFS(WuMin,$Y$12:$Y$60,1,$Z$12:$Z$60,"<="&$Z28)) | AB28: =IF(AND($Y28=1,$AA28<=$B$6),1,0) -> 0 | AC28: =INDEX(WuPhaseN,17)*1000+17 -> 3017 | AD28: =IF($AB28=0,"",COUNTIFS($AB$12:$AB$60,1,$AC$12:$AC$60,"<"&$AC28)+1) | AF28: =IF(OR(INDEX(MoTarget,17)="Always",COUNTIF($E$30:$E$51,INDEX(MoTarget,17))>0,COUNTIF($F$30:$F$51,"*"&INDEX(MoTarget,17)&"*")>0),1,0) -> 1 | AG28: =INDEX(MoPriority,17)*1000+17 -> 4017 | AH28: =IF($AF28=0,"",SUMIFS(MoMin,$AF$12:$AF$54,1,$AG$12:$AG$54,"<="&$AG28)) -> 58 | AI28: =IF(AND($AF28=1,$AH28<=$B$7),1,0) -> 0 | AJ28: =INDEX(MoTypeN,17)*1000+17 -> 2017 | AK28: =IF($AI28=0,"",COUNTIFS($AI$12:$AI$54,1,$AJ$12:$AJ$54,"<"&$AJ28)+1)
A29: # | B29: Exercise | C29: Equipment | D29: Pattern | E29: Primary | F29: Secondary | G29: Profile | H29: Sets | I29: Reps | J29: Load | K29: Suggested kg | L29: Rest | M29: Coaching note | N29: Your load (kg) | O29: Comment | P29: Est. min | Y29: =IF(OR(INDEX(WuTrigger,18)="Always",COUNTIF($D$30:$D$51,INDEX(WuTrigger,18))>0,COUNTIF($E$30:$E$51,INDEX(WuTrigger,18))>0),1,0) -> 0 | Z29: =INDEX(WuPriority,18)*1000+18 -> 6018 | AA29: =IF($Y29=0,"",SUMIFS(WuMin,$Y$12:$Y$60,1,$Z$12:$Z$60,"<="&$Z29)) | AB29: =IF(AND($Y29=1,$AA29<=$B$6),1,0) -> 0 | AC29: =INDEX(WuPhaseN,18)*1000+18 -> 2018 | AD29: =IF($AB29=0,"",COUNTIFS($AB$12:$AB$60,1,$AC$12:$AC$60,"<"&$AC29)+1) | AF29: =IF(OR(INDEX(MoTarget,18)="Always",COUNTIF($E$30:$E$51,INDEX(MoTarget,18))>0,COUNTIF($F$30:$F$51,"*"&INDEX(MoTarget,18)&"*")>0),1,0) -> 0 | AG29: =INDEX(MoPriority,18)*1000+18 -> 2018 | AH29: =IF($AF29=0,"",SUMIFS(MoMin,$AF$12:$AF$54,1,$AG$12:$AG$54,"<="&$AG29)) | AI29: =IF(AND($AF29=1,$AH29<=$B$7),1,0) -> 0 | AJ29: =INDEX(MoTypeN,18)*1000+18 -> 2018 | AK29: =IF($AI29=0,"",COUNTIFS($AI$12:$AI$54,1,$AJ$12:$AJ$54,"<"&$AJ29)+1)
A30: 1 | B30: Back Squat | C30: =IF($B30="","",IFERROR(INDEX(ExEquip,MATCH($B30,ExName,0)),"?")) -> Barbell | D30: =IF($B30="","",IFERROR(INDEX(ExPattern,MATCH($B30,ExName,0)),"?")) -> Squat | E30: =IF($B30="","",IFERROR(INDEX(ExPrimary,MATCH($B30,ExName,0)),"?")) -> Quads | F30: =IF($B30="","",IFERROR(INDEX(ExSecondary,MATCH($B30,ExName,0)),"")) -> Glutes, Hamstrings, Core | G30: =IF($B30="","",IFERROR(INDEX(ExProfile,MATCH($B30,ExName,0)),"?")) -> Heavy compound | H30: =IF($G30="","",IFERROR(INDEX(PrSets,MATCH($G30&"|"&$B$5,PrKey,0)),"?")) -> 3–5 | I30: =IF($G30="","",IFERROR(INDEX(PrReps,MATCH($G30&"|"&$B$5,PrKey,0)),"?")) -> 3–6 | J30: =IF($G30="","",IFERROR(INDEX(PrLoad,MATCH($G30&"|"&$B$5,PrKey,0)),"?")) -> 80–90% of 1RM | K30: =IF($B30="","",IF(N($S30)=0,"Bodyweight / RPE",IF(N($R30)=0,"Enter 1RM in library",TEXT(MROUND($R30*$S30,2.5),"0.0")&"–"&TEXT(MROUND($R30*$T30,2.5),"0.0")&" kg"))) -> 80.0–90.0 kg | L30: =IF($G30="","",IFERROR(INDEX(PrRest,MATCH($G30&"|"&$B$5,PrKey,0)),"?")) -> 3–5 min | M30: =IF($G30="","",IFERROR(INDEX(PrNote,MATCH($G30&"|"&$B$5,PrKey,0)),"")) -> RPE 7–9. Leave 1–2 reps in reserve on most sets. | N30: 82.5 | O30: ← example row, just type over it | P30: =IF(OR($B30="",$U30=""),"",IF($U30=0,0,ROUND(($U30*($V30+$W30)+TimeSetup)/60,0))) -> 19 | R30: =IF($B30="","",IFERROR(INDEX(Ex1RM,MATCH($B30,ExName,0)),"")) -> 100 | S30: =IF($G30="","",IFERROR(INDEX(PrMin,MATCH($G30&"|"&$B$5,PrKey,0)),"")) -> 0.8 | T30: =IF($G30="","",IFERROR(INDEX(PrMax,MATCH($G30&"|"&$B$5,PrKey,0)),"")) -> 0.9 | U30: =IF($G30="","",IFERROR(INDEX(PrSetsN,MATCH($G30&"|"&$B$5,PrKey,0)),"")) -> 4 | V30: =IF($G30="","",IFERROR(INDEX(PrWorkS,MATCH($G30&"|"&$B$5,PrKey,0)),"")) -> 20 | W30: =IF($G30="","",IFERROR(INDEX(PrRestS,MATCH($G30&"|"&$B$5,PrKey,0)),"")) -> 240 | Y30: =IF(OR(INDEX(WuTrigger,19)="Always",COUNTIF($D$30:$D$51,INDEX(WuTrigger,19))>0,COUNTIF($E$30:$E$51,INDEX(WuTrigger,19))>0),1,0) -> 0 | Z30: =INDEX(WuPriority,19)*1000+19 -> 4019 | AA30: =IF($Y30=0,"",SUMIFS(WuMin,$Y$12:$Y$60,1,$Z$12:$Z$60,"<="&$Z30)) | AB30: =IF(AND($Y30=1,$AA30<=$B$6),1,0) -> 0 | AC30: =INDEX(WuPhaseN,19)*1000+19 -> 3019 | AD30: =IF($AB30=0,"",COUNTIFS($AB$12:$AB$60,1,$AC$12:$AC$60,"<"&$AC30)+1) | AF30: =IF(OR(INDEX(MoTarget,19)="Always",COUNTIF($E$30:$E$51,INDEX(MoTarget,19))>0,COUNTIF($F$30:$F$51,"*"&INDEX(MoTarget,19)&"*")>0),1,0) -> 0 | AG30: =INDEX(MoPriority,19)*1000+19 -> 3019 | AH30: =IF($AF30=0,"",SUMIFS(MoMin,$AF$12:$AF$54,1,$AG$12:$AG$54,"<="&$AG30)) | AI30: =IF(AND($AF30=1,$AH30<=$B$7),1,0) -> 0 | AJ30: =INDEX(MoTypeN,19)*1000+19 -> 2019 | AK30: =IF($AI30=0,"",COUNTIFS($AI$12:$AI$54,1,$AJ$12:$AJ$54,"<"&$AJ30)+1)
A31: 2 | B31: Romanian Deadlift | C31: =IF($B31="","",IFERROR(INDEX(ExEquip,MATCH($B31,ExName,0)),"?")) -> Barbell | D31: =IF($B31="","",IFERROR(INDEX(ExPattern,MATCH($B31,ExName,0)),"?")) -> Hinge | E31: =IF($B31="","",IFERROR(INDEX(ExPrimary,MATCH($B31,ExName,0)),"?")) -> Hamstrings | F31: =IF($B31="","",IFERROR(INDEX(ExSecondary,MATCH($B31,ExName,0)),"")) -> Glutes, Back | G31: =IF($B31="","",IFERROR(INDEX(ExProfile,MATCH($B31,ExName,0)),"?")) -> Heavy compound | H31: =IF($G31="","",IFERROR(INDEX(PrSets,MATCH($G31&"|"&$B$5,PrKey,0)),"?")) -> 3–5 | I31: =IF($G31="","",IFERROR(INDEX(PrReps,MATCH($G31&"|"&$B$5,PrKey,0)),"?")) -> 3–6 | J31: =IF($G31="","",IFERROR(INDEX(PrLoad,MATCH($G31&"|"&$B$5,PrKey,0)),"?")) -> 80–90% of 1RM | K31: =IF($B31="","",IF(N($S31)=0,"Bodyweight / RPE",IF(N($R31)=0,"Enter 1RM in library",TEXT(MROUND($R31*$S31,2.5),"0.0")&"–"&TEXT(MROUND($R31*$T31,2.5),"0.0")&" kg"))) -> Enter 1RM in library | L31: =IF($G31="","",IFERROR(INDEX(PrRest,MATCH($G31&"|"&$B$5,PrKey,0)),"?")) -> 3–5 min | M31: =IF($G31="","",IFERROR(INDEX(PrNote,MATCH($G31&"|"&$B$5,PrKey,0)),"")) -> RPE 7–9. Leave 1–2 reps in reserve on most sets. | N31: 70 | P31: =IF(OR($B31="",$U31=""),"",IF($U31=0,0,ROUND(($U31*($V31+$W31)+TimeSetup)/60,0))) -> 19 | R31: =IF($B31="","",IFERROR(INDEX(Ex1RM,MATCH($B31,ExName,0)),"")) -> 0 | S31: =IF($G31="","",IFERROR(INDEX(PrMin,MATCH($G31&"|"&$B$5,PrKey,0)),"")) -> 0.8 | T31: =IF($G31="","",IFERROR(INDEX(PrMax,MATCH($G31&"|"&$B$5,PrKey,0)),"")) -> 0.9 | U31: =IF($G31="","",IFERROR(INDEX(PrSetsN,MATCH($G31&"|"&$B$5,PrKey,0)),"")) -> 4 | V31: =IF($G31="","",IFERROR(INDEX(PrWorkS,MATCH($G31&"|"&$B$5,PrKey,0)),"")) -> 20 | W31: =IF($G31="","",IFERROR(INDEX(PrRestS,MATCH($G31&"|"&$B$5,PrKey,0)),"")) -> 240 | Y31: =IF(OR(INDEX(WuTrigger,20)="Always",COUNTIF($D$30:$D$51,INDEX(WuTrigger,20))>0,COUNTIF($E$30:$E$51,INDEX(WuTrigger,20))>0),1,0) -> 0 | Z31: =INDEX(WuPriority,20)*1000+20 -> 5020 | AA31: =IF($Y31=0,"",SUMIFS(WuMin,$Y$12:$Y$60,1,$Z$12:$Z$60,"<="&$Z31)) | AB31: =IF(AND($Y31=1,$AA31<=$B$6),1,0) -> 0 | AC31: =INDEX(WuPhaseN,20)*1000+20 -> 2020 | AD31: =IF($AB31=0,"",COUNTIFS($AB$12:$AB$60,1,$AC$12:$AC$60,"<"&$AC31)+1) | AF31: =IF(OR(INDEX(MoTarget,20)="Always",COUNTIF($E$30:$E$51,INDEX(MoTarget,20))>0,COUNTIF($F$30:$F$51,"*"&INDEX(MoTarget,20)&"*")>0),1,0) -> 0 | AG31: =INDEX(MoPriority,20)*1000+20 -> 4020 | AH31: =IF($AF31=0,"",SUMIFS(MoMin,$AF$12:$AF$54,1,$AG$12:$AG$54,"<="&$AG31)) | AI31: =IF(AND($AF31=1,$AH31<=$B$7),1,0) -> 0 | AJ31: =INDEX(MoTypeN,20)*1000+20 -> 2020 | AK31: =IF($AI31=0,"",COUNTIFS($AI$12:$AI$54,1,$AJ$12:$AJ$54,"<"&$AJ31)+1)
A32: 3 | B32: Bulgarian Split Squat | C32: =IF($B32="","",IFERROR(INDEX(ExEquip,MATCH($B32,ExName,0)),"?")) -> Dumbbell/Kettlebell | D32: =IF($B32="","",IFERROR(INDEX(ExPattern,MATCH($B32,ExName,0)),"?")) -> Lunge/Single-leg | E32: =IF($B32="","",IFERROR(INDEX(ExPrimary,MATCH($B32,ExName,0)),"?")) -> Quads | F32: =IF($B32="","",IFERROR(INDEX(ExSecondary,MATCH($B32,ExName,0)),"")) -> Glutes, Core | G32: =IF($B32="","",IFERROR(INDEX(ExProfile,MATCH($B32,ExName,0)),"?")) -> Compound | H32: =IF($G32="","",IFERROR(INDEX(PrSets,MATCH($G32&"|"&$B$5,PrKey,0)),"?")) -> 3–4 | I32: =IF($G32="","",IFERROR(INDEX(PrReps,MATCH($G32&"|"&$B$5,PrKey,0)),"?")) -> 5–8 | J32: =IF($G32="","",IFERROR(INDEX(PrLoad,MATCH($G32&"|"&$B$5,PrKey,0)),"?")) -> 75–85% of 1RM | K32: =IF($B32="","",IF(N($S32)=0,"Bodyweight / RPE",IF(N($R32)=0,"Enter 1RM in library",TEXT(MROUND($R32*$S32,2.5),"0.0")&"–"&TEXT(MROUND($R32*$T32,2.5),"0.0")&" kg"))) -> Enter 1RM in library | L32: =IF($G32="","",IFERROR(INDEX(PrRest,MATCH($G32&"|"&$B$5,PrKey,0)),"?")) -> 2–3 min | M32: =IF($G32="","",IFERROR(INDEX(PrNote,MATCH($G32&"|"&$B$5,PrKey,0)),"")) -> RPE 7–9. Add load when the top of the rep range feels easy. | N32: 20 | P32: =IF(OR($B32="",$U32=""),"",IF($U32=0,0,ROUND(($U32*($V32+$W32)+TimeSetup)/60,0))) -> 12 | R32: =IF($B32="","",IFERROR(INDEX(Ex1RM,MATCH($B32,ExName,0)),"")) -> 0 | S32: =IF($G32="","",IFERROR(INDEX(PrMin,MATCH($G32&"|"&$B$5,PrKey,0)),"")) -> 0.75 | T32: =IF($G32="","",IFERROR(INDEX(PrMax,MATCH($G32&"|"&$B$5,PrKey,0)),"")) -> 0.85 | U32: =IF($G32="","",IFERROR(INDEX(PrSetsN,MATCH($G32&"|"&$B$5,PrKey,0)),"")) -> 3.5 | V32: =IF($G32="","",IFERROR(INDEX(PrWorkS,MATCH($G32&"|"&$B$5,PrKey,0)),"")) -> 25 | W32: =IF($G32="","",IFERROR(INDEX(PrRestS,MATCH($G32&"|"&$B$5,PrKey,0)),"")) -> 150 | Y32: =IF(OR(INDEX(WuTrigger,21)="Always",COUNTIF($D$30:$D$51,INDEX(WuTrigger,21))>0,COUNTIF($E$30:$E$51,INDEX(WuTrigger,21))>0),1,0) -> 0 | Z32: =INDEX(WuPriority,21)*1000+21 -> 3021 | AA32: =IF($Y32=0,"",SUMIFS(WuMin,$Y$12:$Y$60,1,$Z$12:$Z$60,"<="&$Z32)) | AB32: =IF(AND($Y32=1,$AA32<=$B$6),1,0) -> 0 | AC32: =INDEX(WuPhaseN,21)*1000+21 -> 3021 | AD32: =IF($AB32=0,"",COUNTIFS($AB$12:$AB$60,1,$AC$12:$AC$60,"<"&$AC32)+1) | AF32: =IF(OR(INDEX(MoTarget,21)="Always",COUNTIF($E$30:$E$51,INDEX(MoTarget,21))>0,COUNTIF($F$30:$F$51,"*"&INDEX(MoTarget,21)&"*")>0),1,0) -> 0 | AG32: =INDEX(MoPriority,21)*1000+21 -> 2021 | AH32: =IF($AF32=0,"",SUMIFS(MoMin,$AF$12:$AF$54,1,$AG$12:$AG$54,"<="&$AG32)) | AI32: =IF(AND($AF32=1,$AH32<=$B$7),1,0) -> 0 | AJ32: =INDEX(MoTypeN,21)*1000+21 -> 2021 | AK32: =IF($AI32=0,"",COUNTIFS($AI$12:$AI$54,1,$AJ$12:$AJ$54,"<"&$AJ32)+1)
A33: 4 | B33: Seated Leg Curl | C33: =IF($B33="","",IFERROR(INDEX(ExEquip,MATCH($B33,ExName,0)),"?")) -> Machine | D33: =IF($B33="","",IFERROR(INDEX(ExPattern,MATCH($B33,ExName,0)),"?")) -> Isolation | E33: =IF($B33="","",IFERROR(INDEX(ExPrimary,MATCH($B33,ExName,0)),"?")) -> Hamstrings | F33: =IF($B33="","",IFERROR(INDEX(ExSecondary,MATCH($B33,ExName,0)),"")) -> 0 | G33: =IF($B33="","",IFERROR(INDEX(ExProfile,MATCH($B33,ExName,0)),"?")) -> Isolation | H33: =IF($G33="","",IFERROR(INDEX(PrSets,MATCH($G33&"|"&$B$5,PrKey,0)),"?")) -> 3–4 | I33: =IF($G33="","",IFERROR(INDEX(PrReps,MATCH($G33&"|"&$B$5,PrKey,0)),"?")) -> 6–12 | J33: =IF($G33="","",IFERROR(INDEX(PrLoad,MATCH($G33&"|"&$B$5,PrKey,0)),"?")) -> 70–80% of 1RM | K33: =IF($B33="","",IF(N($S33)=0,"Bodyweight / RPE",IF(N($R33)=0,"Enter 1RM in library",TEXT(MROUND($R33*$S33,2.5),"0.0")&"–"&TEXT(MROUND($R33*$T33,2.5),"0.0")&" kg"))) -> Enter 1RM in library | L33: =IF($G33="","",IFERROR(INDEX(PrRest,MATCH($G33&"|"&$B$5,PrKey,0)),"?")) -> 90–120 s | M33: =IF($G33="","",IFERROR(INDEX(PrNote,MATCH($G33&"|"&$B$5,PrKey,0)),"")) -> RPE 8–9. Full range of motion beats extra load. | N33: 35 | P33: =IF(OR($B33="",$U33=""),"",IF($U33=0,0,ROUND(($U33*($V33+$W33)+TimeSetup)/60,0))) -> 9 | R33: =IF($B33="","",IFERROR(INDEX(Ex1RM,MATCH($B33,ExName,0)),"")) -> 0 | S33: =IF($G33="","",IFERROR(INDEX(PrMin,MATCH($G33&"|"&$B$5,PrKey,0)),"")) -> 0.7 | T33: =IF($G33="","",IFERROR(INDEX(PrMax,MATCH($G33&"|"&$B$5,PrKey,0)),"")) -> 0.8 | U33: =IF($G33="","",IFERROR(INDEX(PrSetsN,MATCH($G33&"|"&$B$5,PrKey,0)),"")) -> 3.5 | V33: =IF($G33="","",IFERROR(INDEX(PrWorkS,MATCH($G33&"|"&$B$5,PrKey,0)),"")) -> 30 | W33: =IF($G33="","",IFERROR(INDEX(PrRestS,MATCH($G33&"|"&$B$5,PrKey,0)),"")) -> 105 | Y33: =IF(OR(INDEX(WuTrigger,22)="Always",COUNTIF($D$30:$D$51,INDEX(WuTrigger,22))>0,COUNTIF($E$30:$E$51,INDEX(WuTrigger,22))>0),1,0) -> 0 | Z33: =INDEX(WuPriority,22)*1000+22 -> 6022 | AA33: =IF($Y33=0,"",SUMIFS(WuMin,$Y$12:$Y$60,1,$Z$12:$Z$60,"<="&$Z33)) | AB33: =IF(AND($Y33=1,$AA33<=$B$6),1,0) -> 0 | AC33: =INDEX(WuPhaseN,22)*1000+22 -> 2022 | AD33: =IF($AB33=0,"",COUNTIFS($AB$12:$AB$60,1,$AC$12:$AC$60,"<"&$AC33)+1) | AF33: =IF(OR(INDEX(MoTarget,22)="Always",COUNTIF($E$30:$E$51,INDEX(MoTarget,22))>0,COUNTIF($F$30:$F$51,"*"&INDEX(MoTarget,22)&"*")>0),1,0) -> 0 | AG33: =INDEX(MoPriority,22)*1000+22 -> 3022 | AH33: =IF($AF33=0,"",SUMIFS(MoMin,$AF$12:$AF$54,1,$AG$12:$AG$54,"<="&$AG33)) | AI33: =IF(AND($AF33=1,$AH33<=$B$7),1,0) -> 0 | AJ33: =INDEX(MoTypeN,22)*1000+22 -> 2022 | AK33: =IF($AI33=0,"",COUNTIFS($AI$12:$AI$54,1,$AJ$12:$AJ$54,"<"&$AJ33)+1)
A34: 5 | B34: Pallof Press | C34: =IF($B34="","",IFERROR(INDEX(ExEquip,MATCH($B34,ExName,0)),"?")) -> Cable | D34: =IF($B34="","",IFERROR(INDEX(ExPattern,MATCH($B34,ExName,0)),"?")) -> Core/Anti-movement | E34: =IF($B34="","",IFERROR(INDEX(ExPrimary,MATCH($B34,ExName,0)),"?")) -> Core | F34: =IF($B34="","",IFERROR(INDEX(ExSecondary,MATCH($B34,ExName,0)),"")) -> Shoulders | G34: =IF($B34="","",IFERROR(INDEX(ExProfile,MATCH($B34,ExName,0)),"?")) -> Core | H34: =IF($G34="","",IFERROR(INDEX(PrSets,MATCH($G34&"|"&$B$5,PrKey,0)),"?")) -> 3–4 | I34: =IF($G34="","",IFERROR(INDEX(PrReps,MATCH($G34&"|"&$B$5,PrKey,0)),"?")) -> 6–12 reps / 20–40 s | J34: =IF($G34="","",IFERROR(INDEX(PrLoad,MATCH($G34&"|"&$B$5,PrKey,0)),"?")) -> Moderate | K34: =IF($B34="","",IF(N($S34)=0,"Bodyweight / RPE",IF(N($R34)=0,"Enter 1RM in library",TEXT(MROUND($R34*$S34,2.5),"0.0")&"–"&TEXT(MROUND($R34*$T34,2.5),"0.0")&" kg"))) -> Bodyweight / RPE | L34: =IF($G34="","",IFERROR(INDEX(PrRest,MATCH($G34&"|"&$B$5,PrKey,0)),"?")) -> 60–90 s | M34: =IF($G34="","",IFERROR(INDEX(PrNote,MATCH($G34&"|"&$B$5,PrKey,0)),"")) -> Add load once you can hold a clean position. | P34: =IF(OR($B34="",$U34=""),"",IF($U34=0,0,ROUND(($U34*($V34+$W34)+TimeSetup)/60,0))) -> 8 | R34: =IF($B34="","",IFERROR(INDEX(Ex1RM,MATCH($B34,ExName,0)),"")) -> 0 | S34: =IF($G34="","",IFERROR(INDEX(PrMin,MATCH($G34&"|"&$B$5,PrKey,0)),"")) -> 0 | T34: =IF($G34="","",IFERROR(INDEX(PrMax,MATCH($G34&"|"&$B$5,PrKey,0)),"")) -> 0 | U34: =IF($G34="","",IFERROR(INDEX(PrSetsN,MATCH($G34&"|"&$B$5,PrKey,0)),"")) -> 3.5 | V34: =IF($G34="","",IFERROR(INDEX(PrWorkS,MATCH($G34&"|"&$B$5,PrKey,0)),"")) -> 35 | W34: =IF($G34="","",IFERROR(INDEX(PrRestS,MATCH($G34&"|"&$B$5,PrKey,0)),"")) -> 75 | Y34: =IF(OR(INDEX(WuTrigger,23)="Always",COUNTIF($D$30:$D$51,INDEX(WuTrigger,23))>0,COUNTIF($E$30:$E$51,INDEX(WuTrigger,23))>0),1,0) -> 0 | Z34: =INDEX(WuPriority,23)*1000+23 -> 3023 | AA34: =IF($Y34=0,"",SUMIFS(WuMin,$Y$12:$Y$60,1,$Z$12:$Z$60,"<="&$Z34)) | AB34: =IF(AND($Y34=1,$AA34<=$B$6),1,0) -> 0 | AC34: =INDEX(WuPhaseN,23)*1000+23 -> 3023 | AD34: =IF($AB34=0,"",COUNTIFS($AB$12:$AB$60,1,$AC$12:$AC$60,"<"&$AC34)+1) | AF34: =IF(OR(INDEX(MoTarget,23)="Always",COUNTIF($E$30:$E$51,INDEX(MoTarget,23))>0,COUNTIF($F$30:$F$51,"*"&INDEX(MoTarget,23)&"*")>0),1,0) -> 0 | AG34: =INDEX(MoPriority,23)*1000+23 -> 4023 | AH34: =IF($AF34=0,"",SUMIFS(MoMin,$AF$12:$AF$54,1,$AG$12:$AG$54,"<="&$AG34)) | AI34: =IF(AND($AF34=1,$AH34<=$B$7),1,0) -> 0 | AJ34: =INDEX(MoTypeN,23)*1000+23 -> 2023 | AK34: =IF($AI34=0,"",COUNTIFS($AI$12:$AI$54,1,$AJ$12:$AJ$54,"<"&$AJ34)+1)
A35: 6 | B35: Farmer's Walk | C35: =IF($B35="","",IFERROR(INDEX(ExEquip,MATCH($B35,ExName,0)),"?")) -> Dumbbell/Kettlebell | D35: =IF($B35="","",IFERROR(INDEX(ExPattern,MATCH($B35,ExName,0)),"?")) -> Carry | E35: =IF($B35="","",IFERROR(INDEX(ExPrimary,MATCH($B35,ExName,0)),"?")) -> Traps | F35: =IF($B35="","",IFERROR(INDEX(ExSecondary,MATCH($B35,ExName,0)),"")) -> Forearms, Core, Glutes | G35: =IF($B35="","",IFERROR(INDEX(ExProfile,MATCH($B35,ExName,0)),"?")) -> Carry | H35: =IF($G35="","",IFERROR(INDEX(PrSets,MATCH($G35&"|"&$B$5,PrKey,0)),"?")) -> 3–5 | I35: =IF($G35="","",IFERROR(INDEX(PrReps,MATCH($G35&"|"&$B$5,PrKey,0)),"?")) -> 20–30 m | J35: =IF($G35="","",IFERROR(INDEX(PrLoad,MATCH($G35&"|"&$B$5,PrKey,0)),"?")) -> 70–90% of max carry | K35: =IF($B35="","",IF(N($S35)=0,"Bodyweight / RPE",IF(N($R35)=0,"Enter 1RM in library",TEXT(MROUND($R35*$S35,2.5),"0.0")&"–"&TEXT(MROUND($R35*$T35,2.5),"0.0")&" kg"))) -> Enter 1RM in library | L35: =IF($G35="","",IFERROR(INDEX(PrRest,MATCH($G35&"|"&$B$5,PrKey,0)),"?")) -> 90–120 s | M35: =IF($G35="","",IFERROR(INDEX(PrNote,MATCH($G35&"|"&$B$5,PrKey,0)),"")) -> Heavy. Grip is usually the limiter. | N35: 60 | P35: =IF(OR($B35="",$U35=""),"",IF($U35=0,0,ROUND(($U35*($V35+$W35)+TimeSetup)/60,0))) -> 11 | R35: =IF($B35="","",IFERROR(INDEX(Ex1RM,MATCH($B35,ExName,0)),"")) -> 0 | S35: =IF($G35="","",IFERROR(INDEX(PrMin,MATCH($G35&"|"&$B$5,PrKey,0)),"")) -> 0.7 | T35: =IF($G35="","",IFERROR(INDEX(PrMax,MATCH($G35&"|"&$B$5,PrKey,0)),"")) -> 0.9 | U35: =IF($G35="","",IFERROR(INDEX(PrSetsN,MATCH($G35&"|"&$B$5,PrKey,0)),"")) -> 4 | V35: =IF($G35="","",IFERROR(INDEX(PrWorkS,MATCH($G35&"|"&$B$5,PrKey,0)),"")) -> 30 | W35: =IF($G35="","",IFERROR(INDEX(PrRestS,MATCH($G35&"|"&$B$5,PrKey,0)),"")) -> 105 | Y35: =IF(OR(INDEX(WuTrigger,24)="Always",COUNTIF($D$30:$D$51,INDEX(WuTrigger,24))>0,COUNTIF($E$30:$E$51,INDEX(WuTrigger,24))>0),1,0) -> 0 | Z35: =INDEX(WuPriority,24)*1000+24 -> 5024 | AA35: =IF($Y35=0,"",SUMIFS(WuMin,$Y$12:$Y$60,1,$Z$12:$Z$60,"<="&$Z35)) | AB35: =IF(AND($Y35=1,$AA35<=$B$6),1,0) -> 0 | AC35: =INDEX(WuPhaseN,24)*1000+24 -> 3024 | AD35: =IF($AB35=0,"",COUNTIFS($AB$12:$AB$60,1,$AC$12:$AC$60,"<"&$AC35)+1) | AF35: =IF(OR(INDEX(MoTarget,24)="Always",COUNTIF($E$30:$E$51,INDEX(MoTarget,24))>0,COUNTIF($F$30:$F$51,"*"&INDEX(MoTarget,24)&"*")>0),1,0) -> 1 | AG35: =INDEX(MoPriority,24)*1000+24 -> 2024 | AH35: =IF($AF35=0,"",SUMIFS(MoMin,$AF$12:$AF$54,1,$AG$12:$AG$54,"<="&$AG35)) -> 19 | AI35: =IF(AND($AF35=1,$AH35<=$B$7),1,0) -> 0 | AJ35: =INDEX(MoTypeN,24)*1000+24 -> 4024 | AK35: =IF($AI35=0,"",COUNTIFS($AI$12:$AI$54,1,$AJ$12:$AJ$54,"<"&$AJ35)+1)
A36: 7 | C36: =IF($B36="","",IFERROR(INDEX(ExEquip,MATCH($B36,ExName,0)),"?")) | D36: =IF($B36="","",IFERROR(INDEX(ExPattern,MATCH($B36,ExName,0)),"?")) | E36: =IF($B36="","",IFERROR(INDEX(ExPrimary,MATCH($B36,ExName,0)),"?")) | F36: =IF($B36="","",IFERROR(INDEX(ExSecondary,MATCH($B36,ExName,0)),"")) | G36: =IF($B36="","",IFERROR(INDEX(ExProfile,MATCH($B36,ExName,0)),"?")) | H36: =IF($G36="","",IFERROR(INDEX(PrSets,MATCH($G36&"|"&$B$5,PrKey,0)),"?")) | I36: =IF($G36="","",IFERROR(INDEX(PrReps,MATCH($G36&"|"&$B$5,PrKey,0)),"?")) | J36: =IF($G36="","",IFERROR(INDEX(PrLoad,MATCH($G36&"|"&$B$5,PrKey,0)),"?")) | K36: =IF($B36="","",IF(N($S36)=0,"Bodyweight / RPE",IF(N($R36)=0,"Enter 1RM in library",TEXT(MROUND($R36*$S36,2.5),"0.0")&"–"&TEXT(MROUND($R36*$T36,2.5),"0.0")&" kg"))) | L36: =IF($G36="","",IFERROR(INDEX(PrRest,MATCH($G36&"|"&$B$5,PrKey,0)),"?")) | M36: =IF($G36="","",IFERROR(INDEX(PrNote,MATCH($G36&"|"&$B$5,PrKey,0)),"")) | P36: =IF(OR($B36="",$U36=""),"",IF($U36=0,0,ROUND(($U36*($V36+$W36)+TimeSetup)/60,0))) | R36: =IF($B36="","",IFERROR(INDEX(Ex1RM,MATCH($B36,ExName,0)),"")) | S36: =IF($G36="","",IFERROR(INDEX(PrMin,MATCH($G36&"|"&$B$5,PrKey,0)),"")) | T36: =IF($G36="","",IFERROR(INDEX(PrMax,MATCH($G36&"|"&$B$5,PrKey,0)),"")) | U36: =IF($G36="","",IFERROR(INDEX(PrSetsN,MATCH($G36&"|"&$B$5,PrKey,0)),"")) | V36: =IF($G36="","",IFERROR(INDEX(PrWorkS,MATCH($G36&"|"&$B$5,PrKey,0)),"")) | W36: =IF($G36="","",IFERROR(INDEX(PrRestS,MATCH($G36&"|"&$B$5,PrKey,0)),"")) | Y36: =IF(OR(INDEX(WuTrigger,25)="Always",COUNTIF($D$30:$D$51,INDEX(WuTrigger,25))>0,COUNTIF($E$30:$E$51,INDEX(WuTrigger,25))>0),1,0) -> 0 | Z36: =INDEX(WuPriority,25)*1000+25 -> 5025 | AA36: =IF($Y36=0,"",SUMIFS(WuMin,$Y$12:$Y$60,1,$Z$12:$Z$60,"<="&$Z36)) | AB36: =IF(AND($Y36=1,$AA36<=$B$6),1,0) -> 0 | AC36: =INDEX(WuPhaseN,25)*1000+25 -> 2025 | AD36: =IF($AB36=0,"",COUNTIFS($AB$12:$AB$60,1,$AC$12:$AC$60,"<"&$AC36)+1) | AF36: =IF(OR(INDEX(MoTarget,25)="Always",COUNTIF($E$30:$E$51,INDEX(MoTarget,25))>0,COUNTIF($F$30:$F$51,"*"&INDEX(MoTarget,25)&"*")>0),1,0) -> 1 | AG36: =INDEX(MoPriority,25)*1000+25 -> 2025 | AH36: =IF($AF36=0,"",SUMIFS(MoMin,$AF$12:$AF$54,1,$AG$12:$AG$54,"<="&$AG36)) -> 22 | AI36: =IF(AND($AF36=1,$AH36<=$B$7),1,0) -> 0 | AJ36: =INDEX(MoTypeN,25)*1000+25 -> 4025 | AK36: =IF($AI36=0,"",COUNTIFS($AI$12:$AI$54,1,$AJ$12:$AJ$54,"<"&$AJ36)+1)
